Workbook

Sheet Daily
A1: DAILY CONTAINER STOCK | AJ1: DATE: | AL1: 46303
A2: LOCATION | C2: FULL INBOUND (BKK) | L2: CURRENT STOCK (BKK) | R2: =AL1 | V2: LOCATION | X2: FULL INBOUND (LCH) | AG2: CURRENT STOCK (LCH) | AM2: =R2
C3: 22GP | D3: 42GP | E3: 45GP | F3: 22RE | G3: 45RE | H3: 22UT | I3: 42UT | J3: 22PC | K3: 42PC | L3: 22GP | M3: 42GP | N3: 45GP | O3: 22RE | P3: 45RE | Q3: 22UT | R3: 42UT | S3: 22PC | T3: 42PC | X3: 22GP | Y3: 42GP | Z3: 45GP | AA3: 22RE | AB3: 45RE | AC3: 22UT | AD3: 42UT | AE3: 22PC | AF3: 42PC | AG3: 22GP | AH3: 42GP | AI3: 45GP | AJ3: 22RE | AK3: 45RE | AL3: 22UT | AM3: 42UT | AN3: 22PC | AO3: 42PC
A4: PAT | B4: TERMINAL | C4: 242 | D4: 1 | E4: 154 | F4: 3 | G4: 6 | L4: 5 | N4: 37 | V4: LCMT | W4: TERMINAL | X4: 42 | Z4: 55 | AB4: 2 | AG4: 8 | AI4: 26
A5: UNITHAI | B5: TERMINAL | C5: 15 | E5: 14 | F5: 1 | L5: 53 | N5: 8 | O5: 6 | V5: ESCO | W5: TERMINAL | X5: 23 | Z5: 78 | AA5: 1 | AB5: 4 | AG5: 89 | AI5: 1
A6: ESCO #2 | B6: ICD | C6: 13 | E6: 24 | G6: 1 | N6: 14 | V6: LCIT | W6: TERMINAL | X6: 3 | Z6: 2
A7: BMTP | B7: ICD | C7: 1 | V7: HPT | W7: TERMINAL | X7: 42 | Z7: 69 | AG7: 70 | AI7: 2
A8: SMART | B8: DEPOT | L8: 706 | N8: 848 | V8: HAST | W8: DEPOT | AG8: 886 | AI8: 281 | AJ8: 7 | AK8: 53
A9: BC2 | B9: DEPOT | L9: 779 | M9: 4 | N9: 475 | O9: 33 | P9: 38 | V9: CELLO | W9: DEPOT | AG9: 22 | AI9: 21
V10: PW | W10: DEPOT | AG10: 1117 | AH10: 2 | AI10: 823 | AL10: 1 | AM10: 2 | AN10: 3 | AO10: 1
A13: LEASE IN | V13: LEASE IN
A14: REPO (E/P) | L14: 220 | V14: REPO (E/P) | AG14: 70 | AI14: 48
A15: TOTAL AT BKK | C15: =SUM(C4:C14) | D15: =SUM(D4:D14) | E15: =SUM(E4:E14) | F15: =SUM(F4:F14) | G15: =SUM(G4:G14) | H15: =SUM(H4:H14) | I15: =SUM(I4:I14) | J15: =SUM(J4:J14) | ... T15: =SUM(T4:T14) | V15: TOTAL AT LCH | X15: =SUM(X4:X14) | Y15: =SUM(Y4:Y14) | Z15: =SUM(Z4:Z14) | AA15: =SUM(AA4:AA14) | AB15: =SUM(AB4:AB14) | AC15: =SUM(AC4:AC14) | AD15: =SUM(AD4:AD14) | AE15: =SUM(AE4:AE14) | AF15: =SUM(AF4:AF14) | AG15: =AG13+AG12+AG11+AG10+AG9+AG8+AG7+AG6+AG5+AG4 | AH15: =AH13+AH12+AH11+AH10+AH9+AH8+AH7+AH6+AH5+AH4 | AI15: =AI13+AI12+AI11+AI10+AI9+AI8+AI7+AI6+AI5+AI4 | AJ15: =AJ13+AJ12+AJ11+AJ10+AJ9+AJ8+AJ7+AJ6+AJ5+AJ4 | AK15: =AK13+AK12+AK11+AK10+AK9+AK8+AK7+AK6+AK5+AK4 | AL15: =AL13+AL12+AL11+AL10+AL9+AL8+AL7+AL6+AL5+AL4 | AM15: =AM13+AM12+AM11+AM10+AM9+AM8+AM7+AM6+AM5+AM4 | AN15: =AN13+AN12+AN11+AN10+AN9+AN8+AN7+AN6+AN5+AN4 | AO15: =AO13+AO12+AO11+AO10+AO9+AO8+AO7+AO6+AO5+AO4
A17: LOCATION | L17: STOCK BALANCE END WK | V17: LOCATION | AG17: STOCK BALANCE END WK
L18: 22GP | M18: 42GP | N18: 45GP | O18: 22RE | P18: 45RE | Q18: 22UT | R18: 42UT | S18: 22PC | T18: 42PC | AG18: 22GP | AH18: 42GP | AI18: 45GP | AJ18: 22RE | AK18: 45RE | AL18: 22UT | AM18: 42UT | AN18: 22PC | AO18: 42PC
A19: REPO IN（E/P） | V19: REPO IN（E/P）
A20: LEASE IN | V20: LEASE IN
A24: TOTAL AT BKK | V24: TOTAL AT BKK
A29: LOCATION | C29: BOOKING (BKK) WK1ST | I29: 08-11/10/2026 | L29: STOCK BALANCE END (BKK) WK1ST | V29: LOCATION | X29: BOOKING (LCH) WK1ST | AD29: 08-11/10/2026 | AG29: STOCK BALANCE END (LCH) WK1ST
C30: 22GP | D30: 42GP | E30: 45GP | F30: 22RE | G30: 45RE | H30: 22UT | I30: 42UT | J30: 22PC | K30: 42PC | L30: 22GP | M30: 42GP | N30: 45GP | O30: 22RE | P30: 45RE | Q30: 22UT | R30: 42UT | S30: 22PC | T30: 42PC | X30: 22GP | Y30: 42GP | Z30: 45GP | AA30: 22RE | AB30: 45RE | AC30: 22UT | AD30: 42UT | AE30: 22PC | AF30: 42PC | AG30: 22GP | AH30: 42GP | AI30: 45GP | AJ30: 22RE | AK30: 45RE | AL30: 22UT | AM30: 42UT | AN30: 22PC | AO30: 42PC
A31: PAT | B31: TERMINAL | C31: 7 | E31: 19 | L31: =SUM(L4-C31) | M31: =SUM(M4-D31) | N31: =SUM(N4-E31) | O31: =SUM(O4-F31) | P31: =SUM(P4-G31) | Q31: =SUM(Q4-H31) | R31: =SUM(R4-I31) | S31: =SUM(S4-J31) | T31: =SUM(T4-K31) | V31: LCMT | W31: TERMINAL
A32: UNITHAI | B32: TERMINAL | C32: 7 | E32: 1 | L32: =SUM(L5-C32) | M32: =SUM(M5-D32) | N32: =SUM(N5-E32) | O32: =SUM(O5-F32) | P32: =SUM(P5-G32) | Q32: =SUM(Q5-H32) | R32: =SUM(R5-I32) | S32: =SUM(S5-J32) | T32: =SUM(T5-K32) | V32: ESCO | W32: TERMINAL
A33: ESCO #2 | B33: ICD | L33: =SUM(L6-C33) | M33: =SUM(M6-D33) | N33: =SUM(N6-E33) | O33: =SUM(O6-F33) | P33: =SUM(P6-G33) | Q33: =SUM(Q6-H33) | R33: =SUM(R6-I33) | S33: =SUM(S6-J33) | T33: =SUM(T6-K33) | V33: LCIT | W33: TERMINAL
A34: BMTP | B34: ICD | L34: =SUM(L7-C34) | M34: =SUM(M7-D34) | N34: =SUM(N7-E34) | O34: =SUM(O7-F34) | P34: =SUM(P7-G34) | Q34: =SUM(Q7-H34) | R34: =SUM(R7-I34) | S34: =SUM(S7-J34) | T34: =SUM(T7-K34) | V34: HPT | W34: TERMINAL
A35: SMART | B35: DEPOT | C35: 69 | E35: 24 | L35: =SUM(L8-C35) | M35: =SUM(M8-D35) | N35: =SUM(N8-E35) | O35: =SUM(O8-F35) | P35: =SUM(P8-G35) | Q35: =SUM(Q8-H35) | R35: =SUM(R8-I35) | S35: =SUM(S8-J35) | T35: =SUM(T8-K35) | V35: HAST | W35: DEPOT | X35: 54 | Z35: 33 | AB35: 20 | AG35: =SUM(AG8-X35) | AH35: =SUM(AH8-Y35) | AI35: =SUM(AI8-Z35) | AJ35: =SUM(AJ8-AA35) | AK35: =SUM(AK8-AB35) | AL35: =SUM(AL8-AC35) | AM35: =SUM(AM8-AD35) | AN35: =SUM(AN8-AE35) | AO35: =SUM(AO8-AF35)
A36: BC2 | B36: DEPOT | C36: 123 | E36: 128 | F36: 2 | G36: 16 | L36: =SUM(L9-C36) | M36: =SUM(M9-D36) | N36: =SUM(N9-E36) | O36: =SUM(O9-F36) | P36: =SUM(P9-G36) | Q36: =SUM(Q9-H36) | R36: =SUM(R9-I36) | S36: =SUM(S9-J36) | T36: =SUM(T9-K36) | V36: CELLO | W36: DEPOT | X36: 5 | Z36: 6 | AG36: =SUM(AG9-X36) | AH36: =SUM(AH9-Y36) | AI36: =SUM(AI9-Z36) | AJ36: =SUM(AJ9-AA36) | AK36: =SUM(AK9-AB36) | AL36: =SUM(AL9-AC36) | AM36: =SUM(AM9-AD36) | AN36: =SUM(AN9-AE36) | AO36: =SUM(AO9-AF36)
L37: =SUM(L10-C37) | M37: =SUM(M10-D37) | N37: =SUM(N10-E37) | O37: =SUM(O10-F37) | P37: =SUM(P10-G37) | Q37: =SUM(Q10-H37) | R37: =SUM(R10-I37) | S37: =SUM(S10-J37) | T37: =SUM(T10-K37) | V37: PW | W37: DEPOT | X37: 200 | Z37: 116 | AE37: 1 | AF37: 1 | AG37: =SUM(AG10-X37) | AH37: =SUM(AH10-Y37) | AI37: =SUM(AI10-Z37) | AJ37: =SUM(AJ10-AA37) | AK37: =SUM(AK10-AB37) | AL37: =SUM(AL10-AC37) | AM37: =SUM(AM10-AD37) | AN37: =SUM(AN10-AE37) | AO37: =SUM(AO10-AF37)
L38: =SUM(L11-C38) | M38: =SUM(M11-D38) | N38: =SUM(N11-E38) | O38: =SUM(O11-F38) | P38: =SUM(P11-G38) | Q38: =SUM(Q11-H38) | R38: =SUM(R11-I38) | S38: =SUM(S11-J38) | T38: =SUM(T11-K38) | AG38: =SUM(AG11-X38) | AH38: =SUM(AH11-Y38) | AI38: =SUM(AI11-Z38) | AJ38: =SUM(AJ11-AA38) | AK38: =SUM(AK11-AB38) | AL38: =SUM(AL11-AC38) | AM38: =SUM(AM11-AD38) | AN38: =SUM(AN11-AE38) | AO38: =SUM(AO11-AF38)
L39: =SUM(L12-C39) | M39: =SUM(M12-D39) | N39: =SUM(N12-E39) | O39: =SUM(O12-F39) | P39: =SUM(P12-G39) | Q39: =SUM(Q12-H39) | R39: =SUM(R12-I39) | S39: =SUM(S12-J39) | T39: =SUM(T12-K39) | AG39: =SUM(AG12-X39) | AH39: =SUM(AH12-Y39) | AI39: =SUM(AI12-Z39) | AJ39: =SUM(AJ12-AA39) | AK39: =SUM(AK12-AB39) | AL39: =SUM(AL12-AC39) | AM39: =SUM(AM12-AD39) | AN39: =SUM(AN12-AE39) | AO39: =SUM(AO12-AF39)
A40: LEASE IN | L40: =SUM(L13-C40) | M40: =SUM(M13-D40) | N40: =SUM(N13-E40) | O40: =SUM(O13-F40) | P40: =SUM(P13-G40) | Q40: =SUM(Q13-H40) | R40: =SUM(R13-I40) | S40: =SUM(S13-J40) | T40: =SUM(T13-K40) | V40: LEASE IN | AG40: =SUM(AG13-X40) | AH40: =SUM(AH13-Y40) | AI40: =SUM(AI13-Z40) | AJ40: =SUM(AJ13-AA40) | AK40: =SUM(AK13-AB40) | AL40: =SUM(AL13-AC40) | AM40: =SUM(AM13-AD40) | AN40: =SUM(AN13-AE40) | AO40: =SUM(AO13-AF40)
C41: =SUM(C31:C40) | D41: =SUM(D31:D40) | E41: =SUM(E31:E40) | F41: =SUM(F31:F40) | G41: =SUM(G31:G40) | H41: =SUM(H31:H40) | I41: =SUM(I31:I40) | J41: =SUM(J31:J40) | ... T41: =SUM(T31:T40) | V41: TOTAL AT LCH | X41: =SUM(X31:X40) | Y41: =SUM(Y31:Y40) | Z41: =SUM(Z31:Z40) | AA41: =SUM(AA31:AA40) | AB41: =SUM(AB31:AB40) | AC41: =SUM(AC31:AC40) | AD41: =SUM(AD31:AD40) | AE41: =SUM(AE31:AE40) | ... AO41: =SUM(AO31:AO40)
A43: LOCATION | C43: BOOKING (BKK) WK2ND | I43: 12-18/10/2026 | L43: STOCK BALANCE END (BKK) WK2ND | V43: LOCATION | X43: BOOKING (LCH) WK2ND | AD43: 12-18/10/2026 | AG43: STOCK BALANCE END (LCH) WK2ND
C44: 22GP | D44: 42GP | E44: 45GP | F44: 22RE | G44: 45RE | H44: 22UT | I44: 42UT | J44: 22PC | K44: 42PC | L44: 22GP | M44: 42GP | N44: 45GP | O44: 22RE | P44: 45RE | Q44: 22UT | R44: 42UT | S44: 22PC | T44: 42PC | X44: 22GP | Y44: 42GP | Z44: 45GP | AA44: 22RE | AB44: 45RE | AC44: 22UT | AD44: 42UT | AE44: 22PC | AF44: 42PC | AG44: 22GP | AH44: 42GP | AI44: 45GP | AJ44: 22RE | AK44: 45RE | AL44: 22UT | AM44: 42UT | AN44: 22PC | AO44: 42PC
A45: PAT | B45: TERMINAL | C45: 13 | E45: 35 | L45: =SUM(L31-C45) | M45: =SUM(M31-D45) | N45: =SUM(N31-E45) | O45: =SUM(O31-F45) | P45: =SUM(P31-G45) | Q45: =SUM(Q31-H45) | R45: =SUM(R31-I45) | S45: =SUM(S31-J45) | T45: =SUM(T31-K45) | V45: LCMT | W45: TERMINAL
A46: UNITHAI | B46: TERMINAL | C46: 7 | E46: 1 | L46: =SUM(L32-C46) | M46: =SUM(M32-D46) | N46: =SUM(N32-E46) | O46: =SUM(O32-F46) | P46: =SUM(P32-G46) | Q46: =SUM(Q32-H46) | R46: =SUM(R32-I46) | S46: =SUM(S32-J46) | T46: =SUM(T32-K46) | V46: ESCO | W46: TERMINAL
A47: ESCO #2 | B47: ICD | C47: 1 | L47: =SUM(L33-C47) | M47: =SUM(M33-D47) | N47: =SUM(N33-E47) | O47: =SUM(O33-F47) | P47: =SUM(P33-G47) | Q47: =SUM(Q33-H47) | R47: =SUM(R33-I47) | S47: =SUM(S33-J47) | T47: =SUM(T33-K47) | V47: LCIT | W47: TERMINAL
A48: BMTP | B48: ICD | L48: =SUM(L34-C48) | M48: =SUM(M34-D48) | N48: =SUM(N34-E48) | O48: =SUM(O34-F48) | P48: =SUM(P34-G48) | Q48: =SUM(Q34-H48) | R48: =SUM(R34-I48) | S48: =SUM(S34-J48) | T48: =SUM(T34-K48) | V48: HPT | W48: TERMINAL
A49: SMART | B49: DEPOT | C49: 52 | E49: 12 | L49: =SUM(L35-C49) | M49: =SUM(M35-D49) | N49: =SUM(N35-E49) | O49: =SUM(O35-F49) | P49: =SUM(P35-G49) | Q49: =SUM(Q35-H49) | R49: =SUM(R35-I49) | S49: =SUM(S35-J49) | T49: =SUM(T35-K49) | V49: HAST | W49: DEPOT | X49: 69 | Z49: 59 | AA49: 2 | AB49: 35 | AG49: =SUM(AG35-X49) | AH49: =SUM(AH35-Y49) | AI49: =SUM(AI35-Z49) | AJ49: =SUM(AJ35-AA49) | AK49: =SUM(AK35-AB49) | AL49: =SUM(AL35-AC49) | AM49: =SUM(AM35-AD49) | AN49: =SUM(AN35-AE49) | AO49: =SUM(AO35-AF49)
A50: BC2 | B50: DEPOT | C50: 210 | E50: 157 | F50: 4 | G50: 13 | L50: =SUM(L36-C50) | M50: =SUM(M36-D50) | N50: =SUM(N36-E50) | O50: =SUM(O36-F50) | P50: =SUM(P36-G50) | Q50: =SUM(Q36-H50) | R50: =SUM(R36-I50) | S50: =SUM(S36-J50) | T50: =SUM(T36-K50) | V50: CELLO | W50: DEPOT | AG50: =SUM(AG36-X50) | AH50: =SUM(AH36-Y50) | AI50: =SUM(AI36-Z50) | AJ50: =SUM(AJ36-AA50) | AK50: =SUM(AK36-AB50) | AL50: =SUM(AL36-AC50) | AM50: =SUM(AM36-AD50) | AN50: =SUM(AN36-AE50) | AO50: =SUM(AO36-AF50)
L51: =SUM(L37-C51) | M51: =SUM(M37-D51) | N51: =SUM(N37-E51) | O51: =SUM(O37-F51) | P51: =SUM(P37-G51) | Q51: =SUM(Q37-H51) | R51: =SUM(R37-I51) | S51: =SUM(S37-J51) | T51: =SUM(T37-K51) | V51: PW | W51: DEPOT | X51: 238 | Z51: 233 | AB51: 1 | AC51: 1 | AG51: =SUM(AG37-X51) | AH51: =SUM(AH37-Y51) | AI51: =SUM(AI37-Z51) | AJ51: =SUM(AJ37-AA51) | AK51: =SUM(AK37-AB51) | AL51: =SUM(AL37-AC51) | AM51: =SUM(AM37-AD51) | AN51: =SUM(AN37-AE51) | AO51: =SUM(AO37-AF51)
...

Sheet RF SEASONAL
A1: HAL (THBKK) | F1: HAL (THLCH)
A2: YEAR BUILT | B2: CARRIER | C2: DAIKIN | D2: TRMK | F2: YEAR BUILT | G2: CARRIER | H2: DAIKIN | I2: TRMK
B3: 45RE | C3: 45RE | D3: 45RE | G3: 45RE | H3: 45RE | I3: 45RE
A4: 2025 | B4: 3 | D4: 1 | F4: 2025 | G4: 8
A5: 2023 | B5: 1 | F5: 2023 | G5: 2
A6: 2021 | B6: 6 | F6: 2021 | G6: 3
A7: 2020 | B7: 5 | F7: 2020 | G7: 11 | I7: 1
A8: TOTAL | B8: =SUM(B4:B7) | C8: =SUM(C4:C7) | D8: =SUM(D4:D7) | F8: TOTAL | G8: =SUM(G4:G7) | H8: =SUM(H4:H7) | I8: =SUM(I4:I7)

Sheet NEW FORMAT
B1: HAL (THBKK)
B2: Item | C2: 22GP | D2: 42GP | E2: 45GP | F2: 22RE | G2: 45RE | H2: 22UT | I2: 42UT | J2: 22PC | K2: 42PC
B3: Current Stock | C3: =Daily!L15 | D3: =Daily!M15 | E3: =Daily!N15 | F3: =Daily!O15 | G3: =Daily!P15 | H3: =Daily!Q15 | I3: =Daily!R15 | J3: =Daily!S15 | K3: =Daily!T15
B4: E/P In (this week) | C4: =Daily!L14 | D4: =Daily!M14 | E4: =Daily!N14 | F4: =Daily!O14 | G4: =Daily!P14 | H4: =Daily!Q14 | I4: =Daily!R14 | J4: =Daily!S14 | K4: =Daily!T14
B7: INBOUND MT RETURN | C7: =Daily!C15 | D7: =Daily!D15 | E7: =Daily!E15 | F7: =Daily!F15 | G7: =Daily!G15 | H7: =Daily!H15 | I7: =Daily!I15 | J7: =Daily!J15 | K7: =Daily!K15
B8: Booking(This week) | C8: =Daily!C41 | D8: =Daily!D41 | E8: =Daily!E41 | F8: =Daily!F41 | G8: =Daily!G41 | H8: =Daily!H41 | I8: =Daily!I41 | J8: =Daily!J41 | K8: =Daily!K41 | L8: =Daily!I29
B9: Booking(Next week) | C9: =Daily!C55 | D9: =Daily!D55 | E9: =Daily!E55 | F9: =Daily!F55 | G9: =Daily!G55 | H9: =Daily!H55 | I9: =Daily!I55 | J9: =Daily!J55 | K9: =Daily!K55 | L9: =Daily!I43
B10: Balance | C10: =SUM(C3+C4+C5+C6+C7-C8-C9) | D10: =SUM(D3+D4+D5+D6+D7-D8-D9) | E10: =SUM(E3+E4+E5+E6+E7-E8-E9) | F10: =SUM(F3+F4+F5+F6+F7-F8-F9) | G10: =SUM(G3+G4+G5+G6+G7-G8-G9) | H10: =SUM(H3+H4+H5+H6+H7-H8-H9) | I10: =SUM(I3+I4+I5+I6+I7-I8-I9) | J10: =SUM(J3+J4+J5+J6+J7-J8-J9) | K10: =SUM(K3+K4+K5+K6+K7-K8-K9)
B12: HAL (THLCH)
B13: Item | C13: 22GP | D13: 42GP | E13: 45GP | F13: 22RE | G13: 45RE | H13: 22UT | I13: 42UT | J13: 22PC | K13: 42PC
B14: Current Stock | C14: =Daily!AG15 | D14: =Daily!AH15 | E14: =Daily!AI15 | F14: =Daily!AJ15 | G14: =Daily!AK15 | H14: =Daily!AL15 | I14: =Daily!AM15 | J14: =Daily!AN15 | K14: =Daily!AO15
B15: E/P In (this week) | C15: =Daily!AG14 | D15: =Daily!AH14 | E15: =Daily!AI14 | F15: =Daily!AJ14 | G15: =Daily!AK14 | H15: =Daily!AL14 | I15: =Daily!AM14 | J15: =Daily!AN14 | K15: =Daily!AO14
B18: INBOUND MT RETURN | C18: =Daily!X15 | D18: =Daily!Y15 | E18: =Daily!Z15 | F18: =Daily!AA15 | G18: =Daily!AB15 | H18: =Daily!AC15 | I18: =Daily!AD15 | J18: =Daily!AE15 | K18: =Daily!AF15
B19: Booking(This week) | C19: =Daily!X41 | D19: =Daily!Y41 | E19: =Daily!Z41 | F19: =Daily!AA41 | G19: =Daily!AB41 | H19: =Daily!AC41 | I19: =Daily!AD41 | J19: =Daily!AE41 | K19: =Daily!AF41 | L19: =Daily!AD29
B20: Booking(Next week) | C20: =Daily!X55 | D20: =Daily!Y55 | E20: =Daily!Z55 | F20: =Daily!AA55 | G20: =Daily!AB55 | H20: =Daily!AC55 | I20: =Daily!AD55 | J20: =Daily!AE55 | K20: =Daily!AF55 | L20: =Daily!AD43
B21: Balance | C21: =SUM(C14+C15+C16+C17+C18-C19-C20) | D21: =SUM(D14+D15+D16+D17+D18-D19-D20) | E21: =SUM(E14+E15+E16+E17+E18-E19-E20) | F21: =SUM(F14+F15+F16+F17+F18-F19-F20) | G21: =SUM(G14+G15+G16+G17+G18-G19-G20) | H21: =SUM(H14+H15+H16+H17+H18-H19-H20) | I21: =SUM(I14+I15+I16+I17+I18-I19-I20) | J21: =SUM(J14+J15+J16+J17+J18-J19-J20) | K21: =SUM(K14+K15+K16+K17+K18-K19-K20)
